[2025-04-07T10:48:20.279+0000] {local_task_job_runner.py:123} INFO - ::group::Pre task execution logs
[2025-04-07T10:48:20.362+0000] {taskinstance.py:2613} INFO - Dependencies all met for dep_context=non-requeueable deps ti=<TaskInstance: skripsi_perbaikan.wait_for_new_data scheduled__2025-04-07T10:36:00+00:00 [queued]>
[2025-04-07T10:48:20.388+0000] {taskinstance.py:2613} INFO - Dependencies all met for dep_context=requeueable deps ti=<TaskInstance: skripsi_perbaikan.wait_for_new_data scheduled__2025-04-07T10:36:00+00:00 [queued]>
[2025-04-07T10:48:20.391+0000] {taskinstance.py:2866} INFO - Starting attempt 10 of 4
[2025-04-07T10:48:20.473+0000] {taskinstance.py:2889} INFO - Executing <Task(SqlSensor): wait_for_new_data> on 2025-04-07 10:36:00+00:00
[2025-04-07T10:48:20.521+0000] {standard_task_runner.py:104} INFO - Running: ['airflow', 'tasks', 'run', 'skripsi_perbaikan', 'wait_for_new_data', 'scheduled__2025-04-07T10:36:00+00:00', '--job-id', '1038', '--raw', '--subdir', 'DAGS_FOLDER/tugas_akhir.py', '--cfg-path', '/tmp/tmpa0skpmi2']
[2025-04-07T10:48:20.524+0000] {standard_task_runner.py:105} INFO - Job 1038: Subtask wait_for_new_data
[2025-04-07T10:48:20.527+0000] {logging_mixin.py:190} WARNING - /home/airflow/.local/lib/python3.12/site-packages/airflow/task/task_runner/standard_task_runner.py:70 DeprecationWarning: This process (pid=10074) is multi-threaded, use of fork() may lead to deadlocks in the child.
[2025-04-07T10:48:20.532+0000] {standard_task_runner.py:72} INFO - Started process 10140 to run task
[2025-04-07T10:48:20.738+0000] {task_command.py:467} INFO - Running <TaskInstance: skripsi_perbaikan.wait_for_new_data scheduled__2025-04-07T10:36:00+00:00 [running]> on host a9576c91091e
[2025-04-07T10:48:21.046+0000] {taskinstance.py:3132} INFO - Exporting env vars: AIRFLOW_CTX_DAG_OWNER='Dion Rikki' AIRFLOW_CTX_DAG_ID='skripsi_perbaikan' AIRFLOW_CTX_TASK_ID='wait_for_new_data' AIRFLOW_CTX_EXECUTION_DATE='2025-04-07T10:36:00+00:00' AIRFLOW_CTX_TRY_NUMBER='10' AIRFLOW_CTX_DAG_RUN_ID='scheduled__2025-04-07T10:36:00+00:00'
[2025-04-07T10:48:21.063+0000] {logging_mixin.py:190} INFO - Task instance is in running state
[2025-04-07T10:48:21.064+0000] {logging_mixin.py:190} INFO -  Previous state of the Task instance: queued
[2025-04-07T10:48:21.066+0000] {logging_mixin.py:190} INFO - Current task name:wait_for_new_data state:running start_date:2025-04-07 10:48:20.364483+00:00
[2025-04-07T10:48:21.073+0000] {logging_mixin.py:190} INFO - Dag name:skripsi_perbaikan and current dag run status:running
[2025-04-07T10:48:21.077+0000] {taskinstance.py:731} INFO - ::endgroup::
[2025-04-07T10:48:21.143+0000] {base.py:84} INFO - Retrieving connection 'mysql_default'
[2025-04-07T10:48:21.154+0000] {sql.py:101} INFO - Poking: 
            SELECT COUNT(*) 
            FROM tugas_akhir_sensordata s
            WHERE s.timestamp >= NOW() - INTERVAL 5 MINUTE
            AND s.soil_type IS NOT NULL
            AND s.crop_type IS NOT NULL
            AND NOT EXISTS (
                SELECT 1 
                FROM fertilizer_predictions f
                WHERE f.sensor_data_id = s.id
            )
         (with parameters None)
[2025-04-07T10:48:21.174+0000] {base.py:84} INFO - Retrieving connection 'mysql_default'
[2025-04-07T10:48:21.187+0000] {sql.py:553} INFO - Running statement: 
            SELECT COUNT(*) 
            FROM tugas_akhir_sensordata s
            WHERE s.timestamp >= NOW() - INTERVAL 5 MINUTE
            AND s.soil_type IS NOT NULL
            AND s.crop_type IS NOT NULL
            AND NOT EXISTS (
                SELECT 1 
                FROM fertilizer_predictions f
                WHERE f.sensor_data_id = s.id
            )
        , parameters: None
[2025-04-07T10:48:21.191+0000] {sql.py:562} INFO - Rows affected: 1
[2025-04-07T10:48:21.196+0000] {taskinstance.py:3311} ERROR - Task failed with exception
Traceback (most recent call last):
  File "/home/airflow/.local/lib/python3.12/site-packages/airflow/models/taskinstance.py", line 767, in _execute_task
    result = _execute_callable(context=context, **execute_callable_kwargs)
             ^^^^^^^^^^^^^^^^^^^^^^^^^^^^^^^^^^^^^^^^^^^^^^^^^^^^^^^^^^^^^
  File "/home/airflow/.local/lib/python3.12/site-packages/airflow/models/taskinstance.py", line 733, in _execute_callable
    return ExecutionCallableRunner(
           ^^^^^^^^^^^^^^^^^^^^^^^^
  File "/home/airflow/.local/lib/python3.12/site-packages/airflow/utils/operator_helpers.py", line 252, in run
    return self.func(*args, **kwargs)
           ^^^^^^^^^^^^^^^^^^^^^^^^^^
  File "/home/airflow/.local/lib/python3.12/site-packages/airflow/models/baseoperator.py", line 422, in wrapper
    return func(self, *args, **kwargs)
           ^^^^^^^^^^^^^^^^^^^^^^^^^^^
  File "/home/airflow/.local/lib/python3.12/site-packages/airflow/sensors/base.py", line 323, in execute
    raise AirflowSensorTimeout(message)
airflow.exceptions.AirflowSensorTimeout: Sensor has timed out; run duration of 613.394391 seconds exceeds the specified timeout of 600.0.
[2025-04-07T10:48:21.214+0000] {logging_mixin.py:190} INFO - Task instance in failure state
[2025-04-07T10:48:21.217+0000] {logging_mixin.py:190} INFO - Task start:2025-04-07 10:48:20.364483+00:00 end:2025-04-07 10:48:21.212827+00:00 duration:0.848344
[2025-04-07T10:48:21.219+0000] {logging_mixin.py:190} INFO - Task:<Task(SqlSensor): wait_for_new_data> dag:<DAG: skripsi_perbaikan> dagrun:<DagRun skripsi_perbaikan @ 2025-04-07 10:36:00+00:00: scheduled__2025-04-07T10:36:00+00:00, state:running, queued_at: 2025-04-07 10:38:00.181439+00:00. externally triggered: False>
[2025-04-07T10:48:21.221+0000] {logging_mixin.py:190} INFO - Failure caused by Sensor has timed out; run duration of 613.394391 seconds exceeds the specified timeout of 600.0.
[2025-04-07T10:48:21.226+0000] {taskinstance.py:1225} INFO - Immediate failure requested. Marking task as FAILED. dag_id=skripsi_perbaikan, task_id=wait_for_new_data, run_id=scheduled__2025-04-07T10:36:00+00:00, execution_date=20250407T103600, start_date=20250407T104820, end_date=20250407T104821
[2025-04-07T10:48:21.259+0000] {taskinstance.py:340} INFO - ::group::Post task execution logs
[2025-04-07T10:48:21.264+0000] {standard_task_runner.py:124} ERROR - Failed to execute job 1038 for task wait_for_new_data (Sensor has timed out; run duration of 613.394391 seconds exceeds the specified timeout of 600.0.; 10140)
Traceback (most recent call last):
  File "/home/airflow/.local/lib/python3.12/site-packages/airflow/task/task_runner/standard_task_runner.py", line 117, in _start_by_fork
    ret = args.func(args, dag=self.dag)
          ^^^^^^^^^^^^^^^^^^^^^^^^^^^^^
  File "/home/airflow/.local/lib/python3.12/site-packages/airflow/cli/cli_config.py", line 49, in command
    return func(*args, **kwargs)
           ^^^^^^^^^^^^^^^^^^^^^
  File "/home/airflow/.local/lib/python3.12/site-packages/airflow/utils/cli.py", line 116, in wrapper
    return f(*args, **kwargs)
           ^^^^^^^^^^^^^^^^^^
  File "/home/airflow/.local/lib/python3.12/site-packages/airflow/cli/commands/task_command.py", line 483, in task_run
    task_return_code = _run_task_by_selected_method(args, _dag, ti)
                       ^^^^^^^^^^^^^^^^^^^^^^^^^^^^^^^^^^^^^^^^^^^^
  File "/home/airflow/.local/lib/python3.12/site-packages/airflow/cli/commands/task_command.py", line 256, in _run_task_by_selected_method
    return _run_raw_task(args, ti)
           ^^^^^^^^^^^^^^^^^^^^^^^
  File "/home/airflow/.local/lib/python3.12/site-packages/airflow/cli/commands/task_command.py", line 341, in _run_raw_task
    return ti._run_raw_task(
           ^^^^^^^^^^^^^^^^^
  File "/home/airflow/.local/lib/python3.12/site-packages/airflow/utils/session.py", line 97, in wrapper
    return func(*args, session=session, **kwargs)
           ^^^^^^^^^^^^^^^^^^^^^^^^^^^^^^^^^^^^^^
  File "/home/airflow/.local/lib/python3.12/site-packages/airflow/models/taskinstance.py", line 3005, in _run_raw_task
    return _run_raw_task(
           ^^^^^^^^^^^^^^
  File "/home/airflow/.local/lib/python3.12/site-packages/airflow/models/taskinstance.py", line 273, in _run_raw_task
    TaskInstance._execute_task_with_callbacks(
  File "/home/airflow/.local/lib/python3.12/site-packages/airflow/models/taskinstance.py", line 3159, in _execute_task_with_callbacks
    result = self._execute_task(context, task_orig)
             ^^^^^^^^^^^^^^^^^^^^^^^^^^^^^^^^^^^^^^
  File "/home/airflow/.local/lib/python3.12/site-packages/airflow/models/taskinstance.py", line 3183, in _execute_task
    return _execute_task(self, context, task_orig)
           ^^^^^^^^^^^^^^^^^^^^^^^^^^^^^^^^^^^^^^^
  File "/home/airflow/.local/lib/python3.12/site-packages/airflow/models/taskinstance.py", line 767, in _execute_task
    result = _execute_callable(context=context, **execute_callable_kwargs)
             ^^^^^^^^^^^^^^^^^^^^^^^^^^^^^^^^^^^^^^^^^^^^^^^^^^^^^^^^^^^^^
  File "/home/airflow/.local/lib/python3.12/site-packages/airflow/models/taskinstance.py", line 733, in _execute_callable
    return ExecutionCallableRunner(
           ^^^^^^^^^^^^^^^^^^^^^^^^
  File "/home/airflow/.local/lib/python3.12/site-packages/airflow/utils/operator_helpers.py", line 252, in run
    return self.func(*args, **kwargs)
           ^^^^^^^^^^^^^^^^^^^^^^^^^^
  File "/home/airflow/.local/lib/python3.12/site-packages/airflow/models/baseoperator.py", line 422, in wrapper
    return func(self, *args, **kwargs)
           ^^^^^^^^^^^^^^^^^^^^^^^^^^^
  File "/home/airflow/.local/lib/python3.12/site-packages/airflow/sensors/base.py", line 323, in execute
    raise AirflowSensorTimeout(message)
airflow.exceptions.AirflowSensorTimeout: Sensor has timed out; run duration of 613.394391 seconds exceeds the specified timeout of 600.0.
[2025-04-07T10:48:21.308+0000] {local_task_job_runner.py:266} INFO - Task exited with return code 1
[2025-04-07T10:48:21.387+0000] {taskinstance.py:3895} INFO - 0 downstream tasks scheduled from follow-on schedule check
[2025-04-07T10:48:21.406+0000] {local_task_job_runner.py:245} INFO - ::endgroup::
