[2025-02-25T17:04:38.088+0000] {local_task_job_runner.py:123} INFO - ::group::Pre task execution logs
[2025-02-25T17:04:38.127+0000] {taskinstance.py:2613} INFO - Dependencies all met for dep_context=non-requeueable deps ti=<TaskInstance: tugas_kita.wait_for_new_data manual__2025-02-25T17:00:03.484008+00:00 [queued]>
[2025-02-25T17:04:38.166+0000] {taskinstance.py:2613} INFO - Dependencies all met for dep_context=requeueable deps ti=<TaskInstance: tugas_kita.wait_for_new_data manual__2025-02-25T17:00:03.484008+00:00 [queued]>
[2025-02-25T17:04:38.169+0000] {taskinstance.py:2866} INFO - Starting attempt 2 of 7
[2025-02-25T17:04:38.221+0000] {taskinstance.py:2889} INFO - Executing <Task(SqlSensor): wait_for_new_data> on 2025-02-25 17:00:03.484008+00:00
[2025-02-25T17:04:38.253+0000] {standard_task_runner.py:104} INFO - Running: ['airflow', 'tasks', 'run', 'tugas_kita', 'wait_for_new_data', 'manual__2025-02-25T17:00:03.484008+00:00', '--job-id', '104', '--raw', '--subdir', 'DAGS_FOLDER/tugas_akhir.py', '--cfg-path', '/tmp/tmpeeuml0w_']
[2025-02-25T17:04:38.256+0000] {standard_task_runner.py:105} INFO - Job 104: Subtask wait_for_new_data
[2025-02-25T17:04:38.271+0000] {logging_mixin.py:190} WARNING - /home/airflow/.local/lib/python3.12/site-packages/airflow/task/task_runner/standard_task_runner.py:70 DeprecationWarning: This process (pid=1663) is multi-threaded, use of fork() may lead to deadlocks in the child.
[2025-02-25T17:04:38.273+0000] {standard_task_runner.py:72} INFO - Started process 1740 to run task
[2025-02-25T17:04:38.387+0000] {task_command.py:467} INFO - Running <TaskInstance: tugas_kita.wait_for_new_data manual__2025-02-25T17:00:03.484008+00:00 [running]> on host 15e5b1e5ccc7
[2025-02-25T17:04:38.639+0000] {taskinstance.py:3132} INFO - Exporting env vars: AIRFLOW_CTX_DAG_OWNER='Dion Rikki' AIRFLOW_CTX_DAG_ID='tugas_kita' AIRFLOW_CTX_TASK_ID='wait_for_new_data' AIRFLOW_CTX_EXECUTION_DATE='2025-02-25T17:00:03.484008+00:00' AIRFLOW_CTX_TRY_NUMBER='2' AIRFLOW_CTX_DAG_RUN_ID='manual__2025-02-25T17:00:03.484008+00:00'
[2025-02-25T17:04:38.642+0000] {logging_mixin.py:190} INFO - Task instance is in running state
[2025-02-25T17:04:38.642+0000] {logging_mixin.py:190} INFO -  Previous state of the Task instance: queued
[2025-02-25T17:04:38.645+0000] {logging_mixin.py:190} INFO - Current task name:wait_for_new_data state:running start_date:2025-02-25 17:04:38.128593+00:00
[2025-02-25T17:04:38.646+0000] {logging_mixin.py:190} INFO - Dag name:tugas_kita and current dag run status:running
[2025-02-25T17:04:38.649+0000] {taskinstance.py:731} INFO - ::endgroup::
[2025-02-25T17:04:38.671+0000] {base.py:84} INFO - Retrieving connection 'mysql_default'
[2025-02-25T17:04:38.681+0000] {sql.py:101} INFO - Poking: SELECT COUNT(*) FROM tugas_akhir_sensordata WHERE timestamp >= NOW() - INTERVAL 5 MINUTE (with parameters None)
[2025-02-25T17:04:38.700+0000] {base.py:84} INFO - Retrieving connection 'mysql_default'
[2025-02-25T17:04:38.723+0000] {sql.py:553} INFO - Running statement: SELECT COUNT(*) FROM tugas_akhir_sensordata WHERE timestamp >= NOW() - INTERVAL 5 MINUTE, parameters: None
[2025-02-25T17:04:38.728+0000] {sql.py:562} INFO - Rows affected: 1
[2025-02-25T17:05:24.490+0000] {local_task_job_runner.py:127} ERROR - Received SIGTERM. Terminating subprocesses
[2025-02-25T17:05:24.588+0000] {process_utils.py:132} INFO - Sending 15 to group 1740. PIDs of all processes in the group: [1740]
[2025-02-25T17:05:24.605+0000] {process_utils.py:87} INFO - Sending the signal 15 to group 1740
[2025-02-25T17:05:24.644+0000] {taskinstance.py:3093} ERROR - Received SIGTERM. Terminating subprocesses.
[2025-02-25T17:05:24.751+0000] {taskinstance.py:3311} ERROR - Task failed with exception
Traceback (most recent call last):
  File "/home/airflow/.local/lib/python3.12/site-packages/airflow/models/taskinstance.py", line 767, in _execute_task
    result = _execute_callable(context=context, **execute_callable_kwargs)
             ^^^^^^^^^^^^^^^^^^^^^^^^^^^^^^^^^^^^^^^^^^^^^^^^^^^^^^^^^^^^^
  File "/home/airflow/.local/lib/python3.12/site-packages/airflow/models/taskinstance.py", line 733, in _execute_callable
    return ExecutionCallableRunner(
           ^^^^^^^^^^^^^^^^^^^^^^^^
  File "/home/airflow/.local/lib/python3.12/site-packages/airflow/utils/operator_helpers.py", line 252, in run
    return self.func(*args, **kwargs)
           ^^^^^^^^^^^^^^^^^^^^^^^^^^
  File "/home/airflow/.local/lib/python3.12/site-packages/airflow/models/baseoperator.py", line 422, in wrapper
    return func(self, *args, **kwargs)
           ^^^^^^^^^^^^^^^^^^^^^^^^^^^
  File "/home/airflow/.local/lib/python3.12/site-packages/airflow/sensors/base.py", line 334, in execute
    time.sleep(self._get_next_poke_interval(started_at, run_duration, poke_count))
  File "/home/airflow/.local/lib/python3.12/site-packages/airflow/models/taskinstance.py", line 3095, in signal_handler
    raise AirflowTaskTerminated("Task received SIGTERM signal")
airflow.exceptions.AirflowTaskTerminated: Task received SIGTERM signal
[2025-02-25T17:05:24.812+0000] {logging_mixin.py:190} INFO - Task instance in failure state
[2025-02-25T17:05:24.816+0000] {logging_mixin.py:190} INFO - Task start:2025-02-25 17:04:38.128593+00:00 end:2025-02-25 17:05:24.809575+00:00 duration:46.680982
[2025-02-25T17:05:24.820+0000] {logging_mixin.py:190} INFO - Task:<Task(SqlSensor): wait_for_new_data> dag:<DAG: tugas_kita> dagrun:<DagRun tugas_kita @ 2025-02-25 17:00:03.484008+00:00: manual__2025-02-25T17:00:03.484008+00:00, state:running, queued_at: 2025-02-25 17:00:03.504754+00:00. externally triggered: True>
[2025-02-25T17:05:24.824+0000] {logging_mixin.py:190} INFO - Failure caused by Task received SIGTERM signal
[2025-02-25T17:05:24.827+0000] {taskinstance.py:1225} INFO - Marking task as UP_FOR_RETRY. dag_id=tugas_kita, task_id=wait_for_new_data, run_id=manual__2025-02-25T17:00:03.484008+00:00, execution_date=20250225T170003, start_date=20250225T170438, end_date=20250225T170524
[2025-02-25T17:05:25.117+0000] {taskinstance.py:340} INFO - ::group::Post task execution logs
[2025-02-25T17:05:25.215+0000] {process_utils.py:80} INFO - Process psutil.Process(pid=1740, status='terminated', exitcode=2, started='17:04:37') (1740) terminated with exit code 2
[2025-02-25T17:05:25.240+0000] {local_task_job_runner.py:266} INFO - Task exited with return code 143
[2025-02-25T17:05:25.524+0000] {taskinstance.py:3895} INFO - 0 downstream tasks scheduled from follow-on schedule check
[2025-02-25T17:05:28.302+0000] {standard_task_runner.py:217} INFO - Process not found (most likely exited), stop collecting metrics
[2025-02-25T17:05:28.954+0000] {local_task_job_runner.py:245} INFO - ::endgroup::
