[2025-04-07T11:30:18.197+0000] {local_task_job_runner.py:123} INFO - ::group::Pre task execution logs
[2025-04-07T11:30:18.257+0000] {taskinstance.py:2613} INFO - Dependencies all met for dep_context=non-requeueable deps ti=<TaskInstance: skripsi_perbaikan.wait_for_new_data manual__2025-04-07T11:19:56.888558+00:00 [queued]>
[2025-04-07T11:30:18.291+0000] {taskinstance.py:2613} INFO - Dependencies all met for dep_context=requeueable deps ti=<TaskInstance: skripsi_perbaikan.wait_for_new_data manual__2025-04-07T11:19:56.888558+00:00 [queued]>
[2025-04-07T11:30:18.298+0000] {taskinstance.py:2866} INFO - Starting attempt 10 of 4
[2025-04-07T11:30:18.399+0000] {taskinstance.py:2889} INFO - Executing <Task(SqlSensor): wait_for_new_data> on 2025-04-07 11:19:56.888558+00:00
[2025-04-07T11:30:18.493+0000] {logging_mixin.py:190} WARNING - /home/airflow/.local/lib/python3.12/site-packages/airflow/task/task_runner/standard_task_runner.py:70 DeprecationWarning: This process (pid=34688) is multi-threaded, use of fork() may lead to deadlocks in the child.
[2025-04-07T11:30:18.499+0000] {standard_task_runner.py:104} INFO - Running: ['airflow', 'tasks', 'run', 'skripsi_perbaikan', 'wait_for_new_data', 'manual__2025-04-07T11:19:56.888558+00:00', '--job-id', '1264', '--raw', '--subdir', 'DAGS_FOLDER/tugas_akhir.py', '--cfg-path', '/tmp/tmpy3piuz0j']
[2025-04-07T11:30:18.507+0000] {standard_task_runner.py:105} INFO - Job 1264: Subtask wait_for_new_data
[2025-04-07T11:30:18.506+0000] {standard_task_runner.py:72} INFO - Started process 34746 to run task
[2025-04-07T11:30:18.639+0000] {task_command.py:467} INFO - Running <TaskInstance: skripsi_perbaikan.wait_for_new_data manual__2025-04-07T11:19:56.888558+00:00 [running]> on host a9576c91091e
[2025-04-07T11:30:18.928+0000] {taskinstance.py:3132} INFO - Exporting env vars: AIRFLOW_CTX_DAG_OWNER='Dion Rikki' AIRFLOW_CTX_DAG_ID='skripsi_perbaikan' AIRFLOW_CTX_TASK_ID='wait_for_new_data' AIRFLOW_CTX_EXECUTION_DATE='2025-04-07T11:19:56.888558+00:00' AIRFLOW_CTX_TRY_NUMBER='10' AIRFLOW_CTX_DAG_RUN_ID='manual__2025-04-07T11:19:56.888558+00:00'
[2025-04-07T11:30:18.936+0000] {logging_mixin.py:190} INFO - Task instance is in running state
[2025-04-07T11:30:18.941+0000] {logging_mixin.py:190} INFO -  Previous state of the Task instance: queued
[2025-04-07T11:30:18.943+0000] {logging_mixin.py:190} INFO - Current task name:wait_for_new_data state:running start_date:2025-04-07 11:30:18.261099+00:00
[2025-04-07T11:30:18.947+0000] {logging_mixin.py:190} INFO - Dag name:skripsi_perbaikan and current dag run status:running
[2025-04-07T11:30:18.949+0000] {taskinstance.py:731} INFO - ::endgroup::
[2025-04-07T11:30:18.979+0000] {base.py:84} INFO - Retrieving connection 'mysql_default'
[2025-04-07T11:30:18.986+0000] {sql.py:101} INFO - Poking: 
            SELECT COUNT(*) 
            FROM tugas_akhir_sensordata s
            WHERE s.timestamp >= NOW() - INTERVAL 5 MINUTE
            AND s.soil_type IS NOT NULL
            AND s.crop_type IS NOT NULL
            AND NOT EXISTS (
                SELECT 1 
                FROM fertilizer_predictions f
                WHERE f.sensor_data_id = s.id
            )
         (with parameters None)
[2025-04-07T11:30:18.997+0000] {base.py:84} INFO - Retrieving connection 'mysql_default'
[2025-04-07T11:30:19.006+0000] {sql.py:553} INFO - Running statement: 
            SELECT COUNT(*) 
            FROM tugas_akhir_sensordata s
            WHERE s.timestamp >= NOW() - INTERVAL 5 MINUTE
            AND s.soil_type IS NOT NULL
            AND s.crop_type IS NOT NULL
            AND NOT EXISTS (
                SELECT 1 
                FROM fertilizer_predictions f
                WHERE f.sensor_data_id = s.id
            )
        , parameters: None
[2025-04-07T11:30:19.008+0000] {sql.py:562} INFO - Rows affected: 1
[2025-04-07T11:30:19.012+0000] {taskinstance.py:3311} ERROR - Task failed with exception
Traceback (most recent call last):
  File "/home/airflow/.local/lib/python3.12/site-packages/airflow/models/taskinstance.py", line 767, in _execute_task
    result = _execute_callable(context=context, **execute_callable_kwargs)
             ^^^^^^^^^^^^^^^^^^^^^^^^^^^^^^^^^^^^^^^^^^^^^^^^^^^^^^^^^^^^^
  File "/home/airflow/.local/lib/python3.12/site-packages/airflow/models/taskinstance.py", line 733, in _execute_callable
    return ExecutionCallableRunner(
           ^^^^^^^^^^^^^^^^^^^^^^^^
  File "/home/airflow/.local/lib/python3.12/site-packages/airflow/utils/operator_helpers.py", line 252, in run
    return self.func(*args, **kwargs)
           ^^^^^^^^^^^^^^^^^^^^^^^^^^
  File "/home/airflow/.local/lib/python3.12/site-packages/airflow/models/baseoperator.py", line 422, in wrapper
    return func(self, *args, **kwargs)
           ^^^^^^^^^^^^^^^^^^^^^^^^^^^
  File "/home/airflow/.local/lib/python3.12/site-packages/airflow/sensors/base.py", line 323, in execute
    raise AirflowSensorTimeout(message)
airflow.exceptions.AirflowSensorTimeout: Sensor has timed out; run duration of 611.349358 seconds exceeds the specified timeout of 600.0.
[2025-04-07T11:30:19.030+0000] {logging_mixin.py:190} INFO - Task instance in failure state
[2025-04-07T11:30:19.031+0000] {logging_mixin.py:190} INFO - Task start:2025-04-07 11:30:18.261099+00:00 end:2025-04-07 11:30:19.028932+00:00 duration:0.767833
[2025-04-07T11:30:19.033+0000] {logging_mixin.py:190} INFO - Task:<Task(SqlSensor): wait_for_new_data> dag:<DAG: skripsi_perbaikan> dagrun:<DagRun skripsi_perbaikan @ 2025-04-07 11:19:56.888558+00:00: manual__2025-04-07T11:19:56.888558+00:00, state:running, queued_at: 2025-04-07 11:19:57.001588+00:00. externally triggered: True>
[2025-04-07T11:30:19.034+0000] {logging_mixin.py:190} INFO - Failure caused by Sensor has timed out; run duration of 611.349358 seconds exceeds the specified timeout of 600.0.
[2025-04-07T11:30:19.035+0000] {taskinstance.py:1225} INFO - Immediate failure requested. Marking task as FAILED. dag_id=skripsi_perbaikan, task_id=wait_for_new_data, run_id=manual__2025-04-07T11:19:56.888558+00:00, execution_date=20250407T111956, start_date=20250407T113018, end_date=20250407T113019
[2025-04-07T11:30:19.065+0000] {taskinstance.py:340} INFO - ::group::Post task execution logs
[2025-04-07T11:30:19.066+0000] {standard_task_runner.py:124} ERROR - Failed to execute job 1264 for task wait_for_new_data (Sensor has timed out; run duration of 611.349358 seconds exceeds the specified timeout of 600.0.; 34746)
Traceback (most recent call last):
  File "/home/airflow/.local/lib/python3.12/site-packages/airflow/task/task_runner/standard_task_runner.py", line 117, in _start_by_fork
    ret = args.func(args, dag=self.dag)
          ^^^^^^^^^^^^^^^^^^^^^^^^^^^^^
  File "/home/airflow/.local/lib/python3.12/site-packages/airflow/cli/cli_config.py", line 49, in command
    return func(*args, **kwargs)
           ^^^^^^^^^^^^^^^^^^^^^
  File "/home/airflow/.local/lib/python3.12/site-packages/airflow/utils/cli.py", line 116, in wrapper
    return f(*args, **kwargs)
           ^^^^^^^^^^^^^^^^^^
  File "/home/airflow/.local/lib/python3.12/site-packages/airflow/cli/commands/task_command.py", line 483, in task_run
    task_return_code = _run_task_by_selected_method(args, _dag, ti)
                       ^^^^^^^^^^^^^^^^^^^^^^^^^^^^^^^^^^^^^^^^^^^^
  File "/home/airflow/.local/lib/python3.12/site-packages/airflow/cli/commands/task_command.py", line 256, in _run_task_by_selected_method
    return _run_raw_task(args, ti)
           ^^^^^^^^^^^^^^^^^^^^^^^
  File "/home/airflow/.local/lib/python3.12/site-packages/airflow/cli/commands/task_command.py", line 341, in _run_raw_task
    return ti._run_raw_task(
           ^^^^^^^^^^^^^^^^^
  File "/home/airflow/.local/lib/python3.12/site-packages/airflow/utils/session.py", line 97, in wrapper
    return func(*args, session=session, **kwargs)
           ^^^^^^^^^^^^^^^^^^^^^^^^^^^^^^^^^^^^^^
  File "/home/airflow/.local/lib/python3.12/site-packages/airflow/models/taskinstance.py", line 3005, in _run_raw_task
    return _run_raw_task(
           ^^^^^^^^^^^^^^
  File "/home/airflow/.local/lib/python3.12/site-packages/airflow/models/taskinstance.py", line 273, in _run_raw_task
    TaskInstance._execute_task_with_callbacks(
  File "/home/airflow/.local/lib/python3.12/site-packages/airflow/models/taskinstance.py", line 3159, in _execute_task_with_callbacks
    result = self._execute_task(context, task_orig)
             ^^^^^^^^^^^^^^^^^^^^^^^^^^^^^^^^^^^^^^
  File "/home/airflow/.local/lib/python3.12/site-packages/airflow/models/taskinstance.py", line 3183, in _execute_task
    return _execute_task(self, context, task_orig)
           ^^^^^^^^^^^^^^^^^^^^^^^^^^^^^^^^^^^^^^^
  File "/home/airflow/.local/lib/python3.12/site-packages/airflow/models/taskinstance.py", line 767, in _execute_task
    result = _execute_callable(context=context, **execute_callable_kwargs)
             ^^^^^^^^^^^^^^^^^^^^^^^^^^^^^^^^^^^^^^^^^^^^^^^^^^^^^^^^^^^^^
  File "/home/airflow/.local/lib/python3.12/site-packages/airflow/models/taskinstance.py", line 733, in _execute_callable
    return ExecutionCallableRunner(
           ^^^^^^^^^^^^^^^^^^^^^^^^
  File "/home/airflow/.local/lib/python3.12/site-packages/airflow/utils/operator_helpers.py", line 252, in run
    return self.func(*args, **kwargs)
           ^^^^^^^^^^^^^^^^^^^^^^^^^^
  File "/home/airflow/.local/lib/python3.12/site-packages/airflow/models/baseoperator.py", line 422, in wrapper
    return func(self, *args, **kwargs)
           ^^^^^^^^^^^^^^^^^^^^^^^^^^^
  File "/home/airflow/.local/lib/python3.12/site-packages/airflow/sensors/base.py", line 323, in execute
    raise AirflowSensorTimeout(message)
airflow.exceptions.AirflowSensorTimeout: Sensor has timed out; run duration of 611.349358 seconds exceeds the specified timeout of 600.0.
[2025-04-07T11:30:19.130+0000] {local_task_job_runner.py:266} INFO - Task exited with return code 1
[2025-04-07T11:30:19.191+0000] {taskinstance.py:3895} INFO - 0 downstream tasks scheduled from follow-on schedule check
[2025-04-07T11:30:19.208+0000] {local_task_job_runner.py:245} INFO - ::endgroup::
