[2025-04-21T04:26:17.390+0000] {local_task_job_runner.py:123} INFO - ::group::Pre task execution logs
[2025-04-21T04:26:17.569+0000] {taskinstance.py:2613} INFO - Dependencies all met for dep_context=non-requeueable deps ti=<TaskInstance: perbaikan_skripsi.wait_for_new_data scheduled__2025-04-21T04:14:00+00:00 [queued]>
[2025-04-21T04:26:17.697+0000] {taskinstance.py:2613} INFO - Dependencies all met for dep_context=requeueable deps ti=<TaskInstance: perbaikan_skripsi.wait_for_new_data scheduled__2025-04-21T04:14:00+00:00 [queued]>
[2025-04-21T04:26:17.704+0000] {taskinstance.py:2866} INFO - Starting attempt 10 of 4
[2025-04-21T04:26:17.808+0000] {taskinstance.py:2889} INFO - Executing <Task(SqlSensor): wait_for_new_data> on 2025-04-21 04:14:00+00:00
[2025-04-21T04:26:17.853+0000] {logging_mixin.py:190} WARNING - /home/airflow/.local/lib/python3.12/site-packages/airflow/task/task_runner/standard_task_runner.py:70 DeprecationWarning: This process (pid=11146) is multi-threaded, use of fork() may lead to deadlocks in the child.
[2025-04-21T04:26:17.856+0000] {standard_task_runner.py:72} INFO - Started process 11208 to run task
[2025-04-21T04:26:17.870+0000] {standard_task_runner.py:104} INFO - Running: ['airflow', 'tasks', 'run', 'perbaikan_skripsi', 'wait_for_new_data', 'scheduled__2025-04-21T04:14:00+00:00', '--job-id', '8806', '--raw', '--subdir', 'DAGS_FOLDER/tugas_akhir.py', '--cfg-path', '/tmp/tmpk599c6wi']
[2025-04-21T04:26:17.875+0000] {standard_task_runner.py:105} INFO - Job 8806: Subtask wait_for_new_data
[2025-04-21T04:26:18.479+0000] {task_command.py:467} INFO - Running <TaskInstance: perbaikan_skripsi.wait_for_new_data scheduled__2025-04-21T04:14:00+00:00 [running]> on host a9576c91091e
[2025-04-21T04:26:19.125+0000] {taskinstance.py:3132} INFO - Exporting env vars: AIRFLOW_CTX_DAG_OWNER='Dion Rikki' AIRFLOW_CTX_DAG_ID='perbaikan_skripsi' AIRFLOW_CTX_TASK_ID='wait_for_new_data' AIRFLOW_CTX_EXECUTION_DATE='2025-04-21T04:14:00+00:00' AIRFLOW_CTX_TRY_NUMBER='10' AIRFLOW_CTX_DAG_RUN_ID='scheduled__2025-04-21T04:14:00+00:00'
[2025-04-21T04:26:19.140+0000] {logging_mixin.py:190} INFO - Task instance is in running state
[2025-04-21T04:26:19.144+0000] {logging_mixin.py:190} INFO -  Previous state of the Task instance: queued
[2025-04-21T04:26:19.146+0000] {logging_mixin.py:190} INFO - Current task name:wait_for_new_data state:running start_date:2025-04-21 04:26:17.577952+00:00
[2025-04-21T04:26:19.149+0000] {logging_mixin.py:190} INFO - Dag name:perbaikan_skripsi and current dag run status:running
[2025-04-21T04:26:19.153+0000] {taskinstance.py:731} INFO - ::endgroup::
[2025-04-21T04:26:19.253+0000] {base.py:84} INFO - Retrieving connection 'mysql_default'
[2025-04-21T04:26:19.271+0000] {sql.py:101} INFO - Poking: 
            SELECT COUNT(*) 
            FROM tugas_akhir_sensordata s
            WHERE s.timestamp >= NOW() - INTERVAL 3 MINUTE
            AND s.soil_type IS NOT NULL
            AND s.crop_type IS NOT NULL
            AND NOT EXISTS (
                SELECT 1 
                FROM fertilizer_predictions f
                WHERE f.sensor_data_id = s.id
            )
         (with parameters None)
[2025-04-21T04:26:19.295+0000] {base.py:84} INFO - Retrieving connection 'mysql_default'
[2025-04-21T04:26:19.323+0000] {sql.py:553} INFO - Running statement: 
            SELECT COUNT(*) 
            FROM tugas_akhir_sensordata s
            WHERE s.timestamp >= NOW() - INTERVAL 3 MINUTE
            AND s.soil_type IS NOT NULL
            AND s.crop_type IS NOT NULL
            AND NOT EXISTS (
                SELECT 1 
                FROM fertilizer_predictions f
                WHERE f.sensor_data_id = s.id
            )
        , parameters: None
[2025-04-21T04:26:19.331+0000] {sql.py:562} INFO - Rows affected: 1
[2025-04-21T04:26:19.337+0000] {taskinstance.py:3311} ERROR - Task failed with exception
Traceback (most recent call last):
  File "/home/airflow/.local/lib/python3.12/site-packages/airflow/models/taskinstance.py", line 767, in _execute_task
    result = _execute_callable(context=context, **execute_callable_kwargs)
             ^^^^^^^^^^^^^^^^^^^^^^^^^^^^^^^^^^^^^^^^^^^^^^^^^^^^^^^^^^^^^
  File "/home/airflow/.local/lib/python3.12/site-packages/airflow/models/taskinstance.py", line 733, in _execute_callable
    return ExecutionCallableRunner(
           ^^^^^^^^^^^^^^^^^^^^^^^^
  File "/home/airflow/.local/lib/python3.12/site-packages/airflow/utils/operator_helpers.py", line 252, in run
    return self.func(*args, **kwargs)
           ^^^^^^^^^^^^^^^^^^^^^^^^^^
  File "/home/airflow/.local/lib/python3.12/site-packages/airflow/models/baseoperator.py", line 422, in wrapper
    return func(self, *args, **kwargs)
           ^^^^^^^^^^^^^^^^^^^^^^^^^^^
  File "/home/airflow/.local/lib/python3.12/site-packages/airflow/sensors/base.py", line 323, in execute
    raise AirflowSensorTimeout(message)
airflow.exceptions.AirflowSensorTimeout: Sensor has timed out; run duration of 613.725537 seconds exceeds the specified timeout of 600.0.
[2025-04-21T04:26:19.367+0000] {logging_mixin.py:190} INFO - Task instance in failure state
[2025-04-21T04:26:19.369+0000] {logging_mixin.py:190} INFO - Task start:2025-04-21 04:26:17.577952+00:00 end:2025-04-21 04:26:19.365439+00:00 duration:1.787487
[2025-04-21T04:26:19.377+0000] {logging_mixin.py:190} INFO - Task:<Task(SqlSensor): wait_for_new_data> dag:<DAG: perbaikan_skripsi> dagrun:<DagRun perbaikan_skripsi @ 2025-04-21 04:14:00+00:00: scheduled__2025-04-21T04:14:00+00:00, state:running, queued_at: 2025-04-21 04:16:00.414812+00:00. externally triggered: False>
[2025-04-21T04:26:19.379+0000] {logging_mixin.py:190} INFO - Failure caused by Sensor has timed out; run duration of 613.725537 seconds exceeds the specified timeout of 600.0.
[2025-04-21T04:26:19.381+0000] {taskinstance.py:1225} INFO - Immediate failure requested. Marking task as FAILED. dag_id=perbaikan_skripsi, task_id=wait_for_new_data, run_id=scheduled__2025-04-21T04:14:00+00:00, execution_date=20250421T041400, start_date=20250421T042617, end_date=20250421T042619
[2025-04-21T04:26:19.516+0000] {taskinstance.py:340} INFO - ::group::Post task execution logs
[2025-04-21T04:26:19.526+0000] {standard_task_runner.py:124} ERROR - Failed to execute job 8806 for task wait_for_new_data (Sensor has timed out; run duration of 613.725537 seconds exceeds the specified timeout of 600.0.; 11208)
Traceback (most recent call last):
  File "/home/airflow/.local/lib/python3.12/site-packages/airflow/task/task_runner/standard_task_runner.py", line 117, in _start_by_fork
    ret = args.func(args, dag=self.dag)
          ^^^^^^^^^^^^^^^^^^^^^^^^^^^^^
  File "/home/airflow/.local/lib/python3.12/site-packages/airflow/cli/cli_config.py", line 49, in command
    return func(*args, **kwargs)
           ^^^^^^^^^^^^^^^^^^^^^
  File "/home/airflow/.local/lib/python3.12/site-packages/airflow/utils/cli.py", line 116, in wrapper
    return f(*args, **kwargs)
           ^^^^^^^^^^^^^^^^^^
  File "/home/airflow/.local/lib/python3.12/site-packages/airflow/cli/commands/task_command.py", line 483, in task_run
    task_return_code = _run_task_by_selected_method(args, _dag, ti)
                       ^^^^^^^^^^^^^^^^^^^^^^^^^^^^^^^^^^^^^^^^^^^^
  File "/home/airflow/.local/lib/python3.12/site-packages/airflow/cli/commands/task_command.py", line 256, in _run_task_by_selected_method
    return _run_raw_task(args, ti)
           ^^^^^^^^^^^^^^^^^^^^^^^
  File "/home/airflow/.local/lib/python3.12/site-packages/airflow/cli/commands/task_command.py", line 341, in _run_raw_task
    return ti._run_raw_task(
           ^^^^^^^^^^^^^^^^^
  File "/home/airflow/.local/lib/python3.12/site-packages/airflow/utils/session.py", line 97, in wrapper
    return func(*args, session=session, **kwargs)
           ^^^^^^^^^^^^^^^^^^^^^^^^^^^^^^^^^^^^^^
  File "/home/airflow/.local/lib/python3.12/site-packages/airflow/models/taskinstance.py", line 3005, in _run_raw_task
    return _run_raw_task(
           ^^^^^^^^^^^^^^
  File "/home/airflow/.local/lib/python3.12/site-packages/airflow/models/taskinstance.py", line 273, in _run_raw_task
    TaskInstance._execute_task_with_callbacks(
  File "/home/airflow/.local/lib/python3.12/site-packages/airflow/models/taskinstance.py", line 3159, in _execute_task_with_callbacks
    result = self._execute_task(context, task_orig)
             ^^^^^^^^^^^^^^^^^^^^^^^^^^^^^^^^^^^^^^
  File "/home/airflow/.local/lib/python3.12/site-packages/airflow/models/taskinstance.py", line 3183, in _execute_task
    return _execute_task(self, context, task_orig)
           ^^^^^^^^^^^^^^^^^^^^^^^^^^^^^^^^^^^^^^^
  File "/home/airflow/.local/lib/python3.12/site-packages/airflow/models/taskinstance.py", line 767, in _execute_task
    result = _execute_callable(context=context, **execute_callable_kwargs)
             ^^^^^^^^^^^^^^^^^^^^^^^^^^^^^^^^^^^^^^^^^^^^^^^^^^^^^^^^^^^^^
  File "/home/airflow/.local/lib/python3.12/site-packages/airflow/models/taskinstance.py", line 733, in _execute_callable
    return ExecutionCallableRunner(
           ^^^^^^^^^^^^^^^^^^^^^^^^
  File "/home/airflow/.local/lib/python3.12/site-packages/airflow/utils/operator_helpers.py", line 252, in run
    return self.func(*args, **kwargs)
           ^^^^^^^^^^^^^^^^^^^^^^^^^^
  File "/home/airflow/.local/lib/python3.12/site-packages/airflow/models/baseoperator.py", line 422, in wrapper
    return func(self, *args, **kwargs)
           ^^^^^^^^^^^^^^^^^^^^^^^^^^^
  File "/home/airflow/.local/lib/python3.12/site-packages/airflow/sensors/base.py", line 323, in execute
    raise AirflowSensorTimeout(message)
airflow.exceptions.AirflowSensorTimeout: Sensor has timed out; run duration of 613.725537 seconds exceeds the specified timeout of 600.0.
[2025-04-21T04:26:19.637+0000] {local_task_job_runner.py:266} INFO - Task exited with return code 1
[2025-04-21T04:26:19.809+0000] {taskinstance.py:3895} INFO - 0 downstream tasks scheduled from follow-on schedule check
[2025-04-21T04:26:19.851+0000] {local_task_job_runner.py:245} INFO - ::endgroup::
